# 220611

## Promise 와 try / catch 주의점
```js
function throwNormal() {
  throw new Error('throwNormal');
}
async function throwAsync() {
  throw new Error('throwAsync');
}
function throwPromiseManualReject() {
  return new Promise((resolve, reject) => {
    // Error 만들어서 보내자 추적하기 편하다
    reject(new Error('throwPromiseCallReject'));
  });
}
function throwPromiseCallReject() {
  return Promise.reject(new Error('throwPromiseCallReject'));
}

// 테스트를 위해 IIFE 로 만든거니 신경 NO
// 주석처리 안하면 처음부터 throw 함
(async function () {
try {
  // Catch
  throwNormal();

  // No Catch
  throwAsync();
  throwPromiseManualReject();
  throwPromiseCallReject();

  // Catch
  await throwAsync();
  await throwPromiseManualReject();
  await throwPromiseCallReject();
} catch (e) {
}})();
```
중간 `throwAsync()` `throwPromise()` 를 `catch` 하지 못하는 이유는 각 함수가 실행되기 전에 `try` 를 벗어나기 때문  
예측(!) 하자면 `async function` 와 `Promise` 은 즉시 실행 되지 않고 task queue 로 넘기고 진행되기에  
call stack 이 비워지지 않은 현재 상태에서 실행되지 않고 `try` 을 벗어난 후 실행되게 된다.  
  
이로 이해
```js
try {
  // No Catch!
  Promise.reject(new Error('?'));

  // No Catch!
  new Promise((resolve, reject) => {
    reject(new Error('?'));
  });

  // No Catch!
  Promise.resolve().then(() => {
    throw new Error('?');
  });

} catch (e) {
}

```
등 의 `Promise.reject`, `new Promise(...)` , `Promise`.`then / catch` 안에서의 `throw` 를 `catch` 할 수 없으니 주의 해야 한다.